<sdf version='1.4'>
  <world name='default'>
    <model name='ground_plane'>
      <static>1</static>
      <link name='link'>
        <collision name='collision'>
          <geometry>
            <plane>
              <normal>0 0 1</normal>
              <size>100 100</size>
            </plane>
          </geometry>
          <surface>
            <friction>
              <ode>
                <mu>100</mu>
                <mu2>50</mu2>
              </ode>
            </friction>
            <bounce/>
            <contact>
              <ode/>
            </contact>
          </surface>
          <max_contacts>10</max_contacts>
        </collision>
        <visual name='visual'>
          <cast_shadows>0</cast_shadows>
          <geometry>
            <plane>
              <normal>0 0 1</normal>
              <size>100 100</size>
            </plane>
          </geometry>
          <material>
            <script>
              <uri>file://media/materials/scripts/gazebo.material</uri>
              <name>Gazebo/Grey</name>
            </script>
          </material>
        </visual>
        <velocity_decay>
          <linear>0</linear>
          <angular>0</angular>
        </velocity_decay>
        <self_collide>0</self_collide>
        <kinematic>0</kinematic>
        <gravity>1</gravity>
      </link>
    </model>
    <light name='sun' type='directional'>
      <cast_shadows>1</cast_shadows>
      <pose>0 0 10 0 -0 0</pose>
      <diffuse>0.8 0.8 0.8 1</diffuse>
      <specular>0.2 0.2 0.2 1</specular>
      <attenuation>
        <range>1000</range>
        <constant>0.9</constant>
        <linear>0.01</linear>
        <quadratic>0.001</quadratic>
      </attenuation>
      <direction>-0.5 0.1 -0.9</direction>
    </light>
    <physics type='ode'>
      <max_step_size>0.001</max_step_size>
      <real_time_factor>1</real_time_factor>
      <real_time_update_rate>1000</real_time_update_rate>
      <gravity>0 0 -9.8</gravity>
    </physics>
    <scene>
      <ambient>0.4 0.4 0.4 1</ambient>
      <background>0.7 0.7 0.7 1</background>
      <shadows>1</shadows>
    </scene>
    <spherical_coordinates>
      <surface_model>EARTH_WGS84</surface_model>
      <latitude_deg>0</latitude_deg>
      <longitude_deg>0</longitude_deg>
      <elevation>0</elevation>
      <heading_deg>0</heading_deg>
    </spherical_coordinates>
    <model name='agv'>
      <link name='agv_footprint'>
        <pose>0 0 0 0 -0 0</pose>
        <inertial>
          <pose>3.25363e-05 1.47439e-19 1.48169 0 -0 0</pose>
          <mass>1506.01</mass>
          <inertia>
            <ixx>1009.07</ixx>
            <ixy>7.22451e-21</ixy>
            <ixz>-0.0364221</ixz>
            <iyy>12958.5</iyy>
            <iyz>-1.2619e-16</iyz>
            <izz>13151</izz>
          </inertia>
        </inertial>
        <collision name='agv_footprint_collision_agv_base_link'>
          <pose>0 0 1.2 0 -0 0</pose>
          <geometry>
            <box>
              <size>10 1.6 1.4</size>
            </box>
          </geometry>
          <surface>
            <contact>
              <ode/>
            </contact>
            <friction>
              <ode/>
            </friction>
            <bounce/>
          </surface>
          <max_contacts>10</max_contacts>
        </collision>
        <collision name='agv_footprint_collision_agv_platform'>
          <pose>0 0 2.05 0 -0 0</pose>
          <geometry>
            <box>
              <size>10 3 0.3</size>
            </box>
          </geometry>
          <surface>
            <contact>
              <ode/>
            </contact>
            <friction>
              <ode/>
            </friction>
            <bounce/>
          </surface>
          <max_contacts>10</max_contacts>
        </collision>
        <visual name='agv_footprint_visual'>
          <pose>0 0 0 0 -0 0</pose>
          <geometry>
            <box>
              <size>0.1 0.1 0.1</size>
            </box>
          </geometry>
        </visual>
        <visual name='agv_footprint_visual_agv_base_link'>
          <pose>0 0 1.2 0 -0 0</pose>
          <geometry>
            <box>
              <size>10 1.6 1.4</size>
            </box>
          </geometry>
          <material>
            <script>
              <name>Gazebo/Red</name>
              <uri>__default__</uri>
            </script>
          </material>
        </visual>
        <visual name='agv_footprint_visual_agv_fwd_mark'>
          <pose>4.9 0 2.225 0 -0 0</pose>
          <geometry>
            <box>
              <size>0.2 0.4 0.05</size>
            </box>
          </geometry>
          <material>
            <script>
              <name>Gazebo/Purple</name>
              <uri>__default__</uri>
            </script>
          </material>
        </visual>
        <visual name='agv_footprint_visual_agv_lidar0'>
          <pose>5 1.5 1.07 0 -0 0</pose>
          <geometry>
            <box>
              <size>0.15 0.15 0.15</size>
            </box>
          </geometry>
          <material>
            <script>
              <name>Gazebo/Blue</name>
              <uri>__default__</uri>
            </script>
          </material>
        </visual>
        <visual name='agv_footprint_visual_agv_lidar1'>
          <pose>5 -1.5 1.07 0 -0 0</pose>
          <geometry>
            <box>
              <size>0.15 0.15 0.15</size>
            </box>
          </geometry>
          <material>
            <script>
              <name>Gazebo/Blue</name>
              <uri>__default__</uri>
            </script>
          </material>
        </visual>
        <visual name='agv_footprint_visual_agv_lidar2'>
          <pose>0 1.7 1.07 0 -0 1.5708</pose>
          <geometry>
            <box>
              <size>0.15 0.15 0.15</size>
            </box>
          </geometry>
          <material>
            <script>
              <name>Gazebo/Blue</name>
              <uri>__default__</uri>
            </script>
          </material>
        </visual>
        <visual name='agv_footprint_visual_agv_lidar3'>
          <pose>0 -1.7 1.07 0 0 -1.5708</pose>
          <geometry>
            <box>
              <size>0.15 0.15 0.15</size>
            </box>
          </geometry>
          <material>
            <script>
              <name>Gazebo/Blue</name>
              <uri>__default__</uri>
            </script>
          </material>
        </visual>
        <visual name='agv_footprint_visual_agv_lidar4'>
          <pose>-5 1.5 1.07 0 -0 3.14159</pose>
          <geometry>
            <box>
              <size>0.15 0.15 0.15</size>
            </box>
          </geometry>
          <material>
            <script>
              <name>Gazebo/Blue</name>
              <uri>__default__</uri>
            </script>
          </material>
        </visual>
        <visual name='agv_footprint_visual_agv_lidar5'>
          <pose>-5 -1.5 1.07 0 -0 3.14159</pose>
          <geometry>
            <box>
              <size>0.15 0.15 0.15</size>
            </box>
          </geometry>
          <material>
            <script>
              <name>Gazebo/Blue</name>
              <uri>__default__</uri>
            </script>
          </material>
        </visual>
        <visual name='agv_footprint_visual_agv_platform'>
          <pose>0 0 2.05 0 -0 0</pose>
          <geometry>
            <box>
              <size>10 3 0.3</size>
            </box>
          </geometry>
          <material>
            <script>
              <name>Gazebo/Orange</name>
              <uri>__default__</uri>
            </script>
          </material>
        </visual>
        <velocity_decay>
          <linear>0</linear>
          <angular>0</angular>
        </velocity_decay>
        <velocity_decay>
          <linear>0</linear>
          <angular>0</angular>
        </velocity_decay>
        <velocity_decay>
          <linear>0</linear>
          <angular>0</angular>
        </velocity_decay>
        <velocity_decay>
          <linear>0</linear>
          <angular>0</angular>
        </velocity_decay>
        <velocity_decay>
          <linear>0</linear>
          <angular>0</angular>
        </velocity_decay>
        <sensor name='lidar0' type='ray'>
          <visualize>1</visualize>
          <update_rate>10</update_rate>
          <ray>
            <scan>
              <horizontal>
                <samples>360</samples>
                <resolution>1</resolution>
                <min_angle>-1.5</min_angle>
                <max_angle>1.5</max_angle>
              </horizontal>
            </scan>
            <range>
              <min>0.1</min>
              <max>50</max>
              <resolution>0.01</resolution>
            </range>
            <noise>
              <type>gaussian</type>
              <mean>0</mean>
              <stddev>0.01</stddev>
            </noise>
          </ray>
          <plugin name='agv_lidar0' filename='libgazebo_ros_laser.so'>
            <topicName>agv/fl_lidar</topicName>
            <frameName>agv_lidar0</frameName>
            <robotNamespace>/</robotNamespace>
          </plugin>
          <pose>5 1.5 1.07 0 -0 0</pose>
        </sensor>
        <velocity_decay>
          <linear>0</linear>
          <angular>0</angular>
        </velocity_decay>
        <velocity_decay>
          <linear>0</linear>
          <angular>0</angular>
        </velocity_decay>
        <sensor name='lidar1' type='ray'>
          <visualize>1</visualize>
          <update_rate>10</update_rate>
          <ray>
            <scan>
              <horizontal>
                <samples>360</samples>
                <resolution>1</resolution>
                <min_angle>-1.5</min_angle>
                <max_angle>1.5</max_angle>
              </horizontal>
            </scan>
            <range>
              <min>0.1</min>
              <max>50</max>
              <resolution>0.01</resolution>
            </range>
            <noise>
              <type>gaussian</type>
              <mean>0</mean>
              <stddev>0.01</stddev>
            </noise>
          </ray>
          <plugin name='agv_lidar1' filename='libgazebo_ros_laser.so'>
            <topicName>agv/fr_lidar</topicName>
            <frameName>agv_lidar1</frameName>
            <robotNamespace>/</robotNamespace>
          </plugin>
          <pose>5 -1.5 1.07 0 -0 0</pose>
        </sensor>
        <velocity_decay>
          <linear>0</linear>
          <angular>0</angular>
        </velocity_decay>
        <gravity>1</gravity>
        <velocity_decay>
          <linear>0</linear>
          <angular>0</angular>
        </velocity_decay>
        <self_collide>0</self_collide>
        <sensor name='lidar2' type='ray'>
          <visualize>1</visualize>
          <update_rate>10</update_rate>
          <ray>
            <scan>
              <horizontal>
                <samples>360</samples>
                <resolution>1</resolution>
                <min_angle>-1.5</min_angle>
                <max_angle>1.5</max_angle>
              </horizontal>
            </scan>
            <range>
              <min>0.1</min>
              <max>50</max>
              <resolution>0.01</resolution>
            </range>
            <noise>
              <type>gaussian</type>
              <mean>0</mean>
              <stddev>0.01</stddev>
            </noise>
          </ray>
          <plugin name='agv_lidar2' filename='libgazebo_ros_laser.so'>
            <topicName>agv/sl_lidar</topicName>
            <frameName>agv_lidar2</frameName>
            <robotNamespace>/</robotNamespace>
          </plugin>
          <pose>0 1.7 1.07 0 -0 1.5708</pose>
        </sensor>
        <gravity>1</gravity>
        <velocity_decay>
          <linear>0</linear>
          <angular>0</angular>
        </velocity_decay>
        <self_collide>0</self_collide>
        <gravity>1</gravity>
        <self_collide>1</self_collide>
        <gravity>1</gravity>
        <velocity_decay>
          <linear>0</linear>
          <angular>0</angular>
        </velocity_decay>
        <self_collide>0</self_collide>
        <sensor name='lidar3' type='ray'>
          <visualize>1</visualize>
          <update_rate>10</update_rate>
          <ray>
            <scan>
              <horizontal>
                <samples>360</samples>
                <resolution>1</resolution>
                <min_angle>-1.5</min_angle>
                <max_angle>1.5</max_angle>
              </horizontal>
            </scan>
            <range>
              <min>0.1</min>
              <max>50</max>
              <resolution>0.01</resolution>
            </range>
            <noise>
              <type>gaussian</type>
              <mean>0</mean>
              <stddev>0.01</stddev>
            </noise>
          </ray>
          <plugin name='agv_lidar3' filename='libgazebo_ros_laser.so'>
            <topicName>agv/sr_lidar</topicName>
            <frameName>agv_lidar3</frameName>
            <robotNamespace>/</robotNamespace>
          </plugin>
          <pose>0 -1.7 1.07 0 0 -1.5708</pose>
        </sensor>
        <gravity>1</gravity>
        <velocity_decay>
          <linear>0</linear>
          <angular>0</angular>
        </velocity_decay>
        <self_collide>0</self_collide>
        <gravity>1</gravity>
        <self_collide>1</self_collide>
        <gravity>1</gravity>
        <velocity_decay>
          <linear>0</linear>
          <angular>0</angular>
        </velocity_decay>
        <self_collide>0</self_collide>
        <sensor name='lidar4' type='ray'>
          <visualize>1</visualize>
          <update_rate>10</update_rate>
          <ray>
            <scan>
              <horizontal>
                <samples>360</samples>
                <resolution>1</resolution>
                <min_angle>-1.5</min_angle>
                <max_angle>1.5</max_angle>
              </horizontal>
            </scan>
            <range>
              <min>0.1</min>
              <max>50</max>
              <resolution>0.01</resolution>
            </range>
            <noise>
              <type>gaussian</type>
              <mean>0</mean>
              <stddev>0.01</stddev>
            </noise>
          </ray>
          <plugin name='agv_lidar4' filename='libgazebo_ros_laser.so'>
            <topicName>agv/bl_lidar</topicName>
            <frameName>agv_lidar4</frameName>
            <robotNamespace>/</robotNamespace>
          </plugin>
          <pose>-5 1.5 1.07 0 -0 3.14159</pose>
        </sensor>
        <gravity>1</gravity>
        <velocity_decay>
          <linear>0</linear>
          <angular>0</angular>
        </velocity_decay>
        <self_collide>0</self_collide>
        <gravity>1</gravity>
        <self_collide>1</self_collide>
        <gravity>1</gravity>
        <velocity_decay>
          <linear>0</linear>
          <angular>0</angular>
        </velocity_decay>
        <self_collide>0</self_collide>
        <sensor name='lidar5' type='ray'>
          <visualize>1</visualize>
          <update_rate>10</update_rate>
          <ray>
            <scan>
              <horizontal>
                <samples>360</samples>
                <resolution>1</resolution>
                <min_angle>-1.5</min_angle>
                <max_angle>1.5</max_angle>
              </horizontal>
            </scan>
            <range>
              <min>0.1</min>
              <max>50</max>
              <resolution>0.01</resolution>
            </range>
            <noise>
              <type>gaussian</type>
              <mean>0</mean>
              <stddev>0.01</stddev>
            </noise>
          </ray>
          <plugin name='agv_lidar5' filename='libgazebo_ros_laser.so'>
            <topicName>agv/br_lidar</topicName>
            <frameName>agv_lidar5</frameName>
            <robotNamespace>/</robotNamespace>
          </plugin>
          <pose>-5 -1.5 1.07 0 -0 3.14159</pose>
        </sensor>
        <kinematic>0</kinematic>
      </link>
      <link name='agv_bl_hinge'>
        <pose>-2.9 1.4 1.4 0 -0 0</pose>
        <inertial>
          <pose>0 0 0 0 -0 0</pose>
          <mass>10</mass>
          <inertia>
            <ixx>0.8383</ixx>
            <ixy>0</ixy>
            <ixz>0</ixz>
            <iyy>0.8383</iyy>
            <iyz>0</iyz>
            <izz>0.0166</izz>
          </inertia>
        </inertial>
        <visual name='agv_bl_hinge_visual'>
          <pose>0 0 0 0 -0 0</pose>
          <geometry>
            <box>
              <size>0.1 0.1 1</size>
            </box>
          </geometry>
          <material>
            <script>
              <name>Gazebo/Green</name>
              <uri>__default__</uri>
            </script>
          </material>
        </visual>
        <gravity>1</gravity>
        <velocity_decay>
          <linear>0</linear>
          <angular>0</angular>
        </velocity_decay>
        <self_collide>0</self_collide>
        <gravity>1</gravity>
        <self_collide>0</self_collide>
        <kinematic>0</kinematic>
      </link>
      <joint name='agv_platform_2_bl_hinge' type='revolute'>
        <child>agv_bl_hinge</child>
        <parent>agv_footprint</parent>
        <axis>
          <xyz>0 0 1</xyz>
          <limit>
            <lower>-0.942478</lower>
            <upper>0.942478</upper>
            <effort>100000</effort>
            <velocity>1</velocity>
          </limit>
          <dynamics>
            <damping>100</damping>
          </dynamics>
        </axis>
      </joint>
      <link name='agv_bl_wheel'>
        <pose>-2.9 1.475 0.9 -1.5708 0 0</pose>
        <inertial>
          <pose>0 0 0 0 -0 0</pose>
          <mass>100</mass>
          <inertia>
            <ixx>20.1898</ixx>
            <ixy>0</ixy>
            <ixz>0</ixz>
            <iyy>20.1898</iyy>
            <iyz>0</iyz>
            <izz>40.5</izz>
          </inertia>
        </inertial>
        <collision name='agv_bl_wheel_collision'>
          <pose>0 0 0 0 -0 0</pose>
          <geometry>
            <cylinder>
              <length>0.05</length>
              <radius>0.9</radius>
            </cylinder>
          </geometry>
          <surface>
            <contact>
              <ode/>
            </contact>
            <friction>
              <ode>
                <mu>1</mu>
                <mu2>1</mu2>
              </ode>
            </friction>
            <bounce/>
          </surface>
          <max_contacts>10</max_contacts>
        </collision>
        <visual name='agv_bl_wheel_visual'>
          <pose>0 0 0 0 -0 0</pose>
          <geometry>
            <cylinder>
              <length>0.3</length>
              <radius>0.9</radius>
            </cylinder>
          </geometry>
          <material>
            <script>
              <name>Gazebo/Grey</name>
              <uri>__default__</uri>
            </script>
          </material>
        </visual>
        <gravity>1</gravity>
        <velocity_decay>
          <linear>0</linear>
          <angular>0</angular>
        </velocity_decay>
        <self_collide>0</self_collide>
        <gravity>1</gravity>
        <self_collide>0</self_collide>
        <kinematic>0</kinematic>
      </link>
      <joint name='agv_bl_hinge_2_wheel' type='revolute'>
        <child>agv_bl_wheel</child>
        <parent>agv_bl_hinge</parent>
        <axis>
          <xyz>0 1 0</xyz>
          <limit>
            <lower>-1e+16</lower>
            <upper>1e+16</upper>
          </limit>
          <dynamics>
            <damping>0.2</damping>
          </dynamics>
        </axis>
      </joint>
      <link name='agv_br_hinge'>
        <pose>-2.9 -1.4 1.4 0 -0 0</pose>
        <inertial>
          <pose>0 0 0 0 -0 0</pose>
          <mass>10</mass>
          <inertia>
            <ixx>0.8383</ixx>
            <ixy>0</ixy>
            <ixz>0</ixz>
            <iyy>0.8383</iyy>
            <iyz>0</iyz>
            <izz>0.0166</izz>
          </inertia>
        </inertial>
        <visual name='agv_br_hinge_visual'>
          <pose>0 0 0 0 -0 0</pose>
          <geometry>
            <box>
              <size>0.1 0.1 1</size>
            </box>
          </geometry>
          <material>
            <script>
              <name>Gazebo/Green</name>
              <uri>__default__</uri>
            </script>
          </material>
        </visual>
        <gravity>1</gravity>
        <velocity_decay>
          <linear>0</linear>
          <angular>0</angular>
        </velocity_decay>
        <self_collide>0</self_collide>
        <gravity>1</gravity>
        <self_collide>0</self_collide>
        <kinematic>0</kinematic>
      </link>
      <joint name='agv_platform_2_br_hinge' type='revolute'>
        <child>agv_br_hinge</child>
        <parent>agv_footprint</parent>
        <axis>
          <xyz>0 0 1</xyz>
          <limit>
            <lower>-0.942478</lower>
            <upper>0.942478</upper>
            <effort>100000</effort>
            <velocity>1</velocity>
          </limit>
          <dynamics>
            <damping>100</damping>
          </dynamics>
        </axis>
      </joint>
      <link name='agv_br_wheel'>
        <pose>-2.9 -1.475 0.9 -1.5708 0 0</pose>
        <inertial>
          <pose>0 0 0 0 -0 0</pose>
          <mass>100</mass>
          <inertia>
            <ixx>20.1898</ixx>
            <ixy>0</ixy>
            <ixz>0</ixz>
            <iyy>20.1898</iyy>
            <iyz>0</iyz>
            <izz>40.5</izz>
          </inertia>
        </inertial>
        <collision name='agv_br_wheel_collision'>
          <pose>0 0 0 0 -0 0</pose>
          <geometry>
            <cylinder>
              <length>0.05</length>
              <radius>0.9</radius>
            </cylinder>
          </geometry>
          <surface>
            <contact>
              <ode/>
            </contact>
            <friction>
              <ode>
                <mu>1</mu>
                <mu2>1</mu2>
              </ode>
            </friction>
            <bounce/>
          </surface>
          <max_contacts>10</max_contacts>
        </collision>
        <visual name='agv_br_wheel_visual'>
          <pose>0 0 0 0 -0 0</pose>
          <geometry>
            <cylinder>
              <length>0.3</length>
              <radius>0.9</radius>
            </cylinder>
          </geometry>
          <material>
            <script>
              <name>Gazebo/Grey</name>
              <uri>__default__</uri>
            </script>
          </material>
        </visual>
        <gravity>1</gravity>
        <velocity_decay>
          <linear>0</linear>
          <angular>0</angular>
        </velocity_decay>
        <self_collide>0</self_collide>
        <gravity>1</gravity>
        <self_collide>0</self_collide>
        <kinematic>0</kinematic>
      </link>
      <joint name='agv_br_hinge_2_wheel' type='revolute'>
        <child>agv_br_wheel</child>
        <parent>agv_br_hinge</parent>
        <axis>
          <xyz>0 1 0</xyz>
          <limit>
            <lower>-1e+16</lower>
            <upper>1e+16</upper>
          </limit>
          <dynamics>
            <damping>0.2</damping>
          </dynamics>
        </axis>
      </joint>
      <link name='agv_fl_hinge'>
        <pose>2.9 1.4 1.4 0 -0 0</pose>
        <inertial>
          <pose>0 0 0 0 -0 0</pose>
          <mass>10</mass>
          <inertia>
            <ixx>0.8383</ixx>
            <ixy>0</ixy>
            <ixz>0</ixz>
            <iyy>0.8383</iyy>
            <iyz>0</iyz>
            <izz>0.0166</izz>
          </inertia>
        </inertial>
        <visual name='agv_fl_hinge_visual'>
          <pose>0 0 0 0 -0 0</pose>
          <geometry>
            <box>
              <size>0.1 0.1 1</size>
            </box>
          </geometry>
          <material>
            <script>
              <name>Gazebo/Green</name>
              <uri>__default__</uri>
            </script>
          </material>
        </visual>
        <gravity>1</gravity>
        <velocity_decay>
          <linear>0</linear>
          <angular>0</angular>
        </velocity_decay>
        <self_collide>0</self_collide>
        <gravity>1</gravity>
        <self_collide>0</self_collide>
        <kinematic>0</kinematic>
      </link>
      <joint name='agv_platform_2_fl_hinge' type='revolute'>
        <child>agv_fl_hinge</child>
        <parent>agv_footprint</parent>
        <axis>
          <xyz>0 0 1</xyz>
          <limit>
            <lower>-0.942478</lower>
            <upper>0.942478</upper>
            <effort>100000</effort>
            <velocity>1</velocity>
          </limit>
          <dynamics>
            <damping>100</damping>
          </dynamics>
        </axis>
      </joint>
      <link name='agv_fl_wheel'>
        <pose>2.9 1.475 0.9 -1.5708 0 0</pose>
        <inertial>
          <pose>0 0 0 0 -0 0</pose>
          <mass>100</mass>
          <inertia>
            <ixx>20.1898</ixx>
            <ixy>0</ixy>
            <ixz>0</ixz>
            <iyy>20.1898</iyy>
            <iyz>0</iyz>
            <izz>40.5</izz>
          </inertia>
        </inertial>
        <collision name='agv_fl_wheel_collision'>
          <pose>0 0 0 0 -0 0</pose>
          <geometry>
            <cylinder>
              <length>0.05</length>
              <radius>0.9</radius>
            </cylinder>
          </geometry>
          <surface>
            <contact>
              <ode/>
            </contact>
            <friction>
              <ode>
                <mu>1</mu>
                <mu2>1</mu2>
              </ode>
            </friction>
            <bounce/>
          </surface>
          <max_contacts>10</max_contacts>
        </collision>
        <visual name='agv_fl_wheel_visual'>
          <pose>0 0 0 0 -0 0</pose>
          <geometry>
            <cylinder>
              <length>0.3</length>
              <radius>0.9</radius>
            </cylinder>
          </geometry>
          <material>
            <script>
              <name>Gazebo/Grey</name>
              <uri>__default__</uri>
            </script>
          </material>
        </visual>
        <gravity>1</gravity>
        <velocity_decay>
          <linear>0</linear>
          <angular>0</angular>
        </velocity_decay>
        <self_collide>0</self_collide>
        <gravity>1</gravity>
        <self_collide>0</self_collide>
        <kinematic>0</kinematic>
      </link>
      <joint name='agv_fl_hinge_2_wheel' type='revolute'>
        <child>agv_fl_wheel</child>
        <parent>agv_fl_hinge</parent>
        <axis>
          <xyz>0 1 0</xyz>
          <limit>
            <lower>-1e+16</lower>
            <upper>1e+16</upper>
          </limit>
          <dynamics>
            <damping>0.2</damping>
          </dynamics>
        </axis>
      </joint>
      <link name='agv_fr_hinge'>
        <pose>2.9 -1.4 1.4 0 -0 0</pose>
        <inertial>
          <pose>0 0 0 0 -0 0</pose>
          <mass>10</mass>
          <inertia>
            <ixx>0.8383</ixx>
            <ixy>0</ixy>
            <ixz>0</ixz>
            <iyy>0.8383</iyy>
            <iyz>0</iyz>
            <izz>0.0166</izz>
          </inertia>
        </inertial>
        <visual name='agv_fr_hinge_visual'>
          <pose>0 0 0 0 -0 0</pose>
          <geometry>
            <box>
              <size>0.1 0.1 1</size>
            </box>
          </geometry>
          <material>
            <script>
              <name>Gazebo/Green</name>
              <uri>__default__</uri>
            </script>
          </material>
        </visual>
        <gravity>1</gravity>
        <velocity_decay>
          <linear>0</linear>
          <angular>0</angular>
        </velocity_decay>
        <self_collide>0</self_collide>
        <gravity>1</gravity>
        <self_collide>0</self_collide>
        <kinematic>0</kinematic>
      </link>
      <joint name='agv_platform_2_fr_hinge' type='revolute'>
        <child>agv_fr_hinge</child>
        <parent>agv_footprint</parent>
        <axis>
          <xyz>0 0 1</xyz>
          <limit>
            <lower>-0.942478</lower>
            <upper>0.942478</upper>
            <effort>100000</effort>
            <velocity>1</velocity>
          </limit>
          <dynamics>
            <damping>100</damping>
          </dynamics>
        </axis>
      </joint>
      <link name='agv_fr_wheel'>
        <pose>2.9 -1.475 0.9 -1.5708 0 0</pose>
        <inertial>
          <pose>0 0 0 0 -0 0</pose>
          <mass>100</mass>
          <inertia>
            <ixx>20.1898</ixx>
            <ixy>0</ixy>
            <ixz>0</ixz>
            <iyy>20.1898</iyy>
            <iyz>0</iyz>
            <izz>40.5</izz>
          </inertia>
        </inertial>
        <collision name='agv_fr_wheel_collision'>
          <pose>0 0 0 0 -0 0</pose>
          <geometry>
            <cylinder>
              <length>0.05</length>
              <radius>0.9</radius>
            </cylinder>
          </geometry>
          <surface>
            <contact>
              <ode/>
            </contact>
            <friction>
              <ode>
                <mu>1</mu>
                <mu2>1</mu2>
              </ode>
            </friction>
            <bounce/>
          </surface>
          <max_contacts>10</max_contacts>
        </collision>
        <visual name='agv_fr_wheel_visual'>
          <pose>0 0 0 0 -0 0</pose>
          <geometry>
            <cylinder>
              <length>0.3</length>
              <radius>0.9</radius>
            </cylinder>
          </geometry>
          <material>
            <script>
              <name>Gazebo/Grey</name>
              <uri>__default__</uri>
            </script>
          </material>
        </visual>
        <gravity>1</gravity>
        <velocity_decay>
          <linear>0</linear>
          <angular>0</angular>
        </velocity_decay>
        <self_collide>0</self_collide>
        <gravity>1</gravity>
        <self_collide>0</self_collide>
        <kinematic>0</kinematic>
      </link>
      <joint name='agv_fr_hinge_2_wheel' type='revolute'>
        <child>agv_fr_wheel</child>
        <parent>agv_fr_hinge</parent>
        <axis>
          <xyz>0 1 0</xyz>
          <limit>
            <lower>-1e+16</lower>
            <upper>1e+16</upper>
          </limit>
          <dynamics>
            <damping>0.2</damping>
          </dynamics>
        </axis>
      </joint>
      <plugin name='agv_ground_truth' filename='libgazebo_ros_p3d.so'>
        <topicName>agv/ground_truth</topicName>
        <frameName>world</frameName>
        <bodyName>agv_footprint</bodyName>
        <gaussianNoise>0.0</gaussianNoise>
        <alwaysOn>true</alwaysOn>
        <updateRate>20.0</updateRate>
        <robotNamespace>/</robotNamespace>
      </plugin>
      <static>0</static>
      <plugin name='gazebo_ros_control' filename='libgazebo_ros_control.so'>
        <robotNamespace>/agv</robotNamespace>
        <controlPeriod>0.001</controlPeriod>
      </plugin>
      <pose>2 6 0.01 0 -0 0</pose>
    </model>
    <state world_name='default'>
      <sim_time>883 859000000</sim_time>
      <real_time>122 647199072</real_time>
      <wall_time>1472078228 891666418</wall_time>
      <model name='Construction Barrel_4'>
        <pose>35.5326 3.26442 -0 1e-06 1.03398e-25 -0.000539</pose>
        <link name='link'>
          <pose>35.5326 3.26442 -0 1e-06 1.03398e-25 -0.000539</pose>
          <velocity>0 0 0 0 -0 0</velocity>
          <acceleration>0 0 0 0 -0 0</acceleration>
          <wrench>0 0 0 0 -0 0</wrench>
        </link>
      </model>
      <model name='Construction Barrel_5'>
        <pose>36.1775 4.19635 -0 -0 -0 -0.000526</pose>
        <link name='link'>
          <pose>36.1775 4.19635 -0 -0 -0 -0.000526</pose>
          <velocity>0 0 0 0 -0 0</velocity>
          <acceleration>0 0 0 0 -0 0</acceleration>
          <wrench>0 0 0 0 -0 0</wrench>
        </link>
      </model>
      <model name='Construction Barrel_6'>
        <pose>36.7794 2.01697 1e-06 -1e-06 -2e-06 -0.000486</pose>
        <link name='link'>
          <pose>36.7794 2.01697 1e-06 -1e-06 -2e-06 -0.000486</pose>
          <velocity>0 0 0 0 -0 0</velocity>
          <acceleration>0 0 0 0 -0 0</acceleration>
          <wrench>0 0 0 0 -0 0</wrench>
        </link>
      </model>
      <model name='agv'>
        <pose>2.14191 6.17233 -7e-06 -0 -0 -0.038888</pose>
        <link name='agv_bl_hinge'>
          <pose>-0.701469 7.68402 1.4 -1e-06 -0 -0.038892</pose>
          <velocity>0.000211 0.000167 0.00648 -8.6e-05 -5e-06 6e-06</velocity>
          <acceleration>0 0 0 0 -0 0</acceleration>
          <wrench>0 0 0 0 -0 0</wrench>
        </link>
        <link name='agv_bl_wheel'>
          <pose>-0.698553 7.75896 0.9 -1.5708 0.023753 -0.038892</pose>
          <velocity>0.000211 0.000116 0.006095 -0.000128 0.000235 2e-06</velocity>
          <acceleration>0 0 0 0 -0 0</acceleration>
          <wrench>0 0 0 0 -0 0</wrench>
        </link>
        <link name='agv_br_hinge'>
          <pose>-0.810329 4.88613 1.4 -2e-06 -0 -0.0389</pose>
          <velocity>0.000221 0.000321 0.006394 -0.000369 -9e-06 -9e-06</velocity>
          <acceleration>0 0 0 0 -0 0</acceleration>
          <wrench>0 0 0 0 -0 0</wrench>
        </link>
        <link name='agv_br_wheel'>
          <pose>-0.813246 4.81119 0.9 -1.5708 0.019559 -0.0389</pose>
          <velocity>0.000227 0.000334 0.006043 -0.000371 0.000252 -2e-06</velocity>
          <acceleration>0 0 0 0 -0 0</acceleration>
          <wrench>0 0 0 0 -0 0</wrench>
        </link>
        <link name='agv_fl_hinge'>
          <pose>5.09415 7.45852 1.4 -1e-06 6.61744e-24 -0.038904</pose>
          <velocity>0.000214 0.000173 0.006493 -9.2e-05 -1.6e-05 1.7e-05</velocity>
          <acceleration>0 0 0 0 -0 0</acceleration>
          <wrench>0 0 0 0 -0 0</wrench>
        </link>
        <link name='agv_fl_wheel'>
          <pose>5.09706 7.53346 0.9 -1.5708 0.020848 -0.038904</pose>
          <velocity>0.00022 0.000122 0.006111 -0.000135 0.000245 5e-06</velocity>
          <acceleration>0 0 0 0 -0 0</acceleration>
          <wrench>0 0 0 0 -0 0</wrench>
        </link>
        <link name='agv_footprint'>
          <pose>2.14191 6.17233 -7e-06 -0 -0 -0.038888</pose>
          <velocity>0.000222 0.000285 0.004564 -1.7e-05 -5e-06 1e-06</velocity>
          <acceleration>0 0 0 0 -0 0</acceleration>
          <wrench>0 0 0 0 -0 0</wrench>
        </link>
        <link name='agv_fr_hinge'>
          <pose>4.98529 4.66064 1.39999 0 -0 -0.038896</pose>
          <velocity>0.000216 0.000311 0.004066 4.5e-05 -9e-06 -7e-06</velocity>
          <acceleration>0 0 0 0 -0 0</acceleration>
          <wrench>0 0 0 0 -0 0</wrench>
        </link>
        <link name='agv_fr_wheel'>
          <pose>4.98237 4.58569 0.9 -1.5708 0.024793 -0.038896</pose>
          <velocity>0.000226 0.000341 0.006023 -0.000379 0.000251 -1e-06</velocity>
          <acceleration>0 0 0 0 -0 0</acceleration>
          <wrench>0 0 0 0 -0 0</wrench>
        </link>
      </model>
      <model name='ground_plane'>
        <pose>0 0 0 0 -0 0</pose>
        <link name='link'>
          <pose>0 0 0 0 -0 0</pose>
          <velocity>0 0 0 0 -0 0</velocity>
          <acceleration>0 0 0 0 -0 0</acceleration>
          <wrench>0 0 0 0 -0 0</wrench>
        </link>
      </model>
    </state>
    <gui fullscreen='0'>
      <camera name='user_camera'>
        <pose>49.8929 -16.8421 7.2174 0 0.119268 2.25455</pose>
        <view_controller>orbit</view_controller>
      </camera>
    </gui>
    <model name='Construction Barrel_4'>
      <link name='link'>
        <inertial>
          <pose>0 0 0.4 0 -0 0</pose>
          <mass>500</mass>
          <inertia>
            <ixx>51.2096</ixx>
            <iyy>51.2096</iyy>
            <izz>25</izz>
            <ixy>0</ixy>
            <ixz>0</ixz>
            <iyz>0</iyz>
          </inertia>
        </inertial>
        <collision name='collision'>
          <geometry>
            <mesh>
              <uri>model://construction_barrel/meshes/construction_barrel.dae</uri>
            </mesh>
          </geometry>
          <max_contacts>10</max_contacts>
          <surface>
            <bounce/>
            <friction>
              <ode/>
            </friction>
            <contact>
              <ode/>
            </contact>
          </surface>
        </collision>
        <visual name='visual'>
          <geometry>
            <mesh>
              <uri>model://construction_barrel/meshes/construction_barrel.dae</uri>
            </mesh>
          </geometry>
        </visual>
        <velocity_decay>
          <linear>0</linear>
          <angular>0</angular>
        </velocity_decay>
        <self_collide>0</self_collide>
        <kinematic>0</kinematic>
        <gravity>1</gravity>
      </link>
      <pose>31 4 0 0 -0 0</pose>
      <static>0</static>
    </model>
    <model name='Construction Barrel_5'>
      <link name='link'>
        <inertial>
          <pose>0 0 0.4 0 -0 0</pose>
          <mass>500</mass>
          <inertia>
            <ixx>51.2096</ixx>
            <iyy>51.2096</iyy>
            <izz>25</izz>
            <ixy>0</ixy>
            <ixz>0</ixz>
            <iyz>0</iyz>
          </inertia>
        </inertial>
        <collision name='collision'>
          <geometry>
            <mesh>
              <uri>model://construction_barrel/meshes/construction_barrel.dae</uri>
            </mesh>
          </geometry>
          <max_contacts>10</max_contacts>
          <surface>
            <bounce/>
            <friction>
              <ode/>
            </friction>
            <contact>
              <ode/>
            </contact>
          </surface>
        </collision>
        <visual name='visual'>
          <geometry>
            <mesh>
              <uri>model://construction_barrel/meshes/construction_barrel.dae</uri>
            </mesh>
          </geometry>
        </visual>
        <velocity_decay>
          <linear>0</linear>
          <angular>0</angular>
        </velocity_decay>
        <self_collide>0</self_collide>
        <kinematic>0</kinematic>
        <gravity>1</gravity>
      </link>
      <pose>28.5253 5.58667 0 0 -0 0</pose>
      <static>0</static>
    </model>
    <model name='Construction Barrel_6'>
      <link name='link'>
        <inertial>
          <pose>0 0 0.4 0 -0 0</pose>
          <mass>500</mass>
          <inertia>
            <ixx>51.2096</ixx>
            <iyy>51.2096</iyy>
            <izz>25</izz>
            <ixy>0</ixy>
            <ixz>0</ixz>
            <iyz>0</iyz>
          </inertia>
        </inertial>
        <collision name='collision'>
          <geometry>
            <mesh>
              <uri>model://construction_barrel/meshes/construction_barrel.dae</uri>
            </mesh>
          </geometry>
          <max_contacts>10</max_contacts>
          <surface>
            <bounce/>
            <friction>
              <ode/>
            </friction>
            <contact>
              <ode/>
            </contact>
          </surface>
        </collision>
        <visual name='visual'>
          <geometry>
            <mesh>
              <uri>model://construction_barrel/meshes/construction_barrel.dae</uri>
            </mesh>
          </geometry>
        </visual>
        <velocity_decay>
          <linear>0</linear>
          <angular>0</angular>
        </velocity_decay>
        <self_collide>0</self_collide>
        <kinematic>0</kinematic>
        <gravity>1</gravity>
      </link>
      <pose>29.5805 3 0 0 -0 0</pose>
      <static>0</static>
    </model>
  </world>
</sdf>
